

2023-12-17 12:55:53 [ERROR]: Freezer, freezer1, was requested to be created. But a freezer with that name already exists. No change has been made.
2023-12-17 12:55:53 [ERROR]: NoneType: None

2023-12-17 12:56:38 [ERROR]: Freezer, freezer1, was requested to be created. But a freezer with that name already exists. No change has been made.
2023-12-17 12:56:38 [ERROR]: NoneType: None

2023-12-17 12:56:38 [ERROR]: An error occurred: UnboundLocalError("cannot access local variable 'e' where it is not associated with a value")
2023-12-17 12:56:38 [ERROR]: Traceback (most recent call last):
  File "c:\Users\bryan\OneDrive\Desktop\Projects\Python\FreezerInv\freezerinv\app.py", line 63, in insert
    logging.info(f"An error occurred: {repr(e)}")
                                            ^
UnboundLocalError: cannot access local variable 'e' where it is not associated with a value

2023-12-19 12:30:56 [ERROR]: An error occurred: UnboundLocalError("cannot access local variable 'e' where it is not associated with a value")
2023-12-19 12:30:56 [ERROR]: Traceback (most recent call last):
  File "c:\Users\bryan\OneDrive\Desktop\Projects\Python\FreezerInv\freezerinv\app.py", line 63, in insert
    logging.info(f"An error occurred: {repr(e)}")
                                            ^
UnboundLocalError: cannot access local variable 'e' where it is not associated with a value

2023-12-19 12:33:18 [ERROR]: An error occurred: UnboundLocalError("cannot access local variable 'item_to_update' where it is not associated with a value")
2023-12-19 12:33:18 [ERROR]: Traceback (most recent call last):
  File "c:\Users\bryan\OneDrive\Desktop\Projects\Python\FreezerInv\freezerinv\app.py", line 124, in update
    item_to_update['item_name'] = str(update_value)
    ^^^^^^^^^^^^^^
UnboundLocalError: cannot access local variable 'item_to_update' where it is not associated with a value

2023-12-19 12:40:43 [ERROR]: An error occurred: TypeError("'str' object does not support item assignment")
2023-12-19 12:40:43 [ERROR]: Traceback (most recent call last):
  File "c:\Users\bryan\OneDrive\Desktop\Projects\Python\FreezerInv\freezerinv\app.py", line 125, in update
    item_to_update['item_name'] = str(update_value)
    ~~~~~~~~~~~~~~^^^^^^^^^^^^^
TypeError: 'str' object does not support item assignment

2023-12-19 12:41:00 [ERROR]: An error occurred: TypeError("'NoneType' object does not support item assignment")
2023-12-19 12:41:00 [ERROR]: Traceback (most recent call last):
  File "c:\Users\bryan\OneDrive\Desktop\Projects\Python\FreezerInv\freezerinv\app.py", line 125, in update
    item_to_update['item_name'] = str(update_value)
    ~~~~~~~~~~~~~~^^^^^^^^^^^^^
TypeError: 'NoneType' object does not support item assignment

2023-12-19 12:44:42 [ERROR]: An error occurred: AttributeError("'str' object has no attribute 'update'")
2023-12-19 12:44:42 [ERROR]: Traceback (most recent call last):
  File "c:\Users\bryan\OneDrive\Desktop\Projects\Python\FreezerInv\freezerinv\app.py", line 128, in update
    freezer.update(item_to_update)
    ^^^^^^^^^^^^^^
AttributeError: 'str' object has no attribute 'update'

2023-12-19 12:45:36 [ERROR]: An error occurred: TypeError("'NoneType' object does not support item assignment")
2023-12-19 12:45:36 [ERROR]: Traceback (most recent call last):
  File "c:\Users\bryan\OneDrive\Desktop\Projects\Python\FreezerInv\freezerinv\app.py", line 128, in update
    item_to_update['item_name'] = str(update_value)
    ~~~~~~~~~~~~~~^^^^^^^^^^^^^
TypeError: 'NoneType' object does not support item assignment

2023-12-19 12:53:23 [ERROR]: An error occurred: TypeError("'NoneType' object does not support item assignment")
2023-12-19 12:53:23 [ERROR]: Traceback (most recent call last):
  File "c:\Users\bryan\OneDrive\Desktop\Projects\Python\FreezerInv\freezerinv\app.py", line 128, in update
    item_to_update['item_name'] = str(update_value)
    ~~~~~~~~~~~~~~^^^^^^^^^^^^^
TypeError: 'NoneType' object does not support item assignment

2023-12-19 13:01:00 [ERROR]: An error occurred: TypeError("'NoneType' object does not support item assignment")
2023-12-19 13:01:00 [ERROR]: Traceback (most recent call last):
  File "c:\Users\bryan\OneDrive\Desktop\Projects\Python\FreezerInv\freezerinv\app.py", line 128, in update
    item_to_update['item_name'] = str(update_value)
    ~~~~~~~~~~~~~~^^^^^^^^^^^^^
TypeError: 'NoneType' object does not support item assignment

2023-12-19 13:29:20 [ERROR]: An error occurred: TypeError("'NoneType' object is not subscriptable")
2023-12-19 13:29:20 [ERROR]: Traceback (most recent call last):
  File "c:\Users\bryan\OneDrive\Desktop\Projects\Python\FreezerInv\freezerinv\app.py", line 128, in update
    print(item_to_update['item_name'])
          ~~~~~~~~~~~~~~^^^^^^^^^^^^^
TypeError: 'NoneType' object is not subscriptable

2023-12-24 11:42:55 [ERROR]: An error occurred: ValueError('dictionary update sequence element #0 has length 1; 2 is required')
2023-12-24 11:42:55 [ERROR]: Traceback (most recent call last):
  File "c:\Users\bryan\OneDrive\Desktop\Projects\Python\FreezerInv\freezerinv\app.py", line 130, in update
    freezer_table.update(item_to_update['item_name'])
  File "C:\Users\bryan\AppData\Local\Programs\Python\Python312\Lib\site-packages\tinydb\table.py", line 453, in update
    self._update_table(updater)
  File "C:\Users\bryan\AppData\Local\Programs\Python\Python312\Lib\site-packages\tinydb\table.py", line 755, in _update_table
    updater(table)
  File "C:\Users\bryan\AppData\Local\Programs\Python\Python312\Lib\site-packages\tinydb\table.py", line 450, in updater
    perform_update(table, doc_id)
  File "C:\Users\bryan\AppData\Local\Programs\Python\Python312\Lib\site-packages\tinydb\table.py", line 391, in perform_update
    table[doc_id].update(fields)
ValueError: dictionary update sequence element #0 has length 1; 2 is required

2023-12-24 11:44:35 [ERROR]: An error occurred: ValueError('dictionary update sequence element #0 has length 1; 2 is required')
2023-12-24 11:44:35 [ERROR]: Traceback (most recent call last):
  File "c:\Users\bryan\OneDrive\Desktop\Projects\Python\FreezerInv\freezerinv\app.py", line 130, in update
    freezer_table.update(item_to_update['item_name'])
  File "C:\Users\bryan\AppData\Local\Programs\Python\Python312\Lib\site-packages\tinydb\table.py", line 453, in update
    self._update_table(updater)
  File "C:\Users\bryan\AppData\Local\Programs\Python\Python312\Lib\site-packages\tinydb\table.py", line 755, in _update_table
    updater(table)
  File "C:\Users\bryan\AppData\Local\Programs\Python\Python312\Lib\site-packages\tinydb\table.py", line 450, in updater
    perform_update(table, doc_id)
  File "C:\Users\bryan\AppData\Local\Programs\Python\Python312\Lib\site-packages\tinydb\table.py", line 391, in perform_update
    table[doc_id].update(fields)
ValueError: dictionary update sequence element #0 has length 1; 2 is required

2023-12-24 11:50:06 [ERROR]: An error occurred: UnboundLocalError("cannot access local variable 'item_to_update' where it is not associated with a value")
2023-12-24 11:50:06 [ERROR]: Traceback (most recent call last):
  File "c:\Users\bryan\OneDrive\Desktop\Projects\Python\FreezerInv\freezerinv\app.py", line 117, in update
    doc_id = freezer_table.search(Query().item_name == item_to_update['item_name'])[0].doc_id
                                                       ^^^^^^^^^^^^^^
UnboundLocalError: cannot access local variable 'item_to_update' where it is not associated with a value

